Workbook
Name Aquarius: ListOption_SIGN!$L$4:$L$57
Name Aries: ListOption_SIGN!$B$4:$B$39
Name Cancer: ListOption_SIGN!$E$4:$E$53
Name Capricorn: ListOption_SIGN!$K$4:$K$58
Name DD_degree_dd: DD_degree[Degree]
Name DD_risingsign_ddown: DD_risingsign[RISING SIGN]
Name DD_sign_dd: DD_sign[SIGN]
Name DD_subject_dd: DD_subject[SUBJECT]
Name DD_TruePlacement1_ddown: DD_TruePlacement1[TruePlacement 1]
Name DD_TruePlacement2_ddown: DD_TruePlacement2[TruePlacement2]
Name Gemini: ListOption_SIGN!$D$4:$D$39
Name JUPITER: ListOption_PLANET!$H$4:$H$61
Name Leo: ListOption_SIGN!$F$4:$F$61
Name Libra: ListOption_SIGN!$H$4:$H$43
Name MARS: ListOption_PLANET!$F$4:$F$39
Name MERCURY: ListOption_PLANET!$E$4:$E$70
Name MOON: ListOption_PLANET!$B$4:$B$53
Name NEPTUNE: ListOption_PLANET!$K$4:$K$55
Name Pisces: ListOption_SIGN!$M$4:$M$55
Name Planet: ListOption_PLANET!$A$4:$A$13
Name PLUTO: ListOption_PLANET!$G$4:$G$51
Name Sagittarius: ListOption_SIGN!$J$4:$J$61
Name SATURN: ListOption_PLANET!$I$4:$I$58
Name Scorpio: ListOption_SIGN!$I$4:$I$51
Name SIGN: ListOption_SIGN!$A$4:$A$15
Name SUN: ListOption_PLANET!$C$4:$C$61
Name Taurus: ListOption_SIGN!$C$4:$C$36
Name URANUS: ListOption_PLANET!$J$4:$J$57
Name VENUS: ListOption_PLANET!$D$4:$D$76
Name Virgo: ListOption_SIGN!$G$4:$G$34

Sheet Spark_calculator
B2: SPARK
R6: =IFERROR(C9&" at "&E9&" in "&G9&" - "&K9&" spark "&" in "&M9&" decan ", "") -> at in - spark in decan
R7: =C12&" at "&E12&" in "&G12&" - "&K12&" spark "&" in "&M12&" decan " -> at in - Not Found spark in Not Found decan
C8: SUBJECT | E8: DEGREE | G8: SIGN | K8: SPARK | M8: Decan | O8: Decan Planets | R8: =C15&" at "&E15&" in "&G15&" - "&K15&" spark "&" in "&M15&" decan " -> at in - Not Found spark in Not Found decan
K9: =IFERROR(VLOOKUP(E9&"-"&G9, Degree_Spark_DataBase[[Helper]:[Decan Planets]], 2, 0),"") | M9: =IFERROR(VLOOKUP(E9&"-"&G9, Degree_Spark_DataBase[[Helper]:[Decan Planets]], 3, 0),"") | O9: =IFERROR(VLOOKUP(E9&"-"&G9, Degree_Spark_DataBase[[Helper]:[Decan Planets]], 4, 0),"")
C11: SUBJECT | E11: DEGREE: | G11: SIGN: | K11: SPARK | M11: Decan | O11: Decan Planets
K12: =IFERROR(VLOOKUP(E12&"-"&G12, Degree_Spark_DataBase[[Helper]:[Decan Planets]], 2, 0),"Not Found") -> Not Found | M12: =IFERROR(VLOOKUP(E12&"-"&G12, Degree_Spark_DataBase[[Helper]:[Decan Planets]], 3, 0),"Not Found") -> Not Found | O12: =IFERROR(VLOOKUP(E12&"-"&G12, Degree_Spark_DataBase[[Helper]:[Decan Planets]], 4, 0),"Not Found") -> Not Found
C14: SUBJECT | E14: DEGREE: | G14: SIGN: | K14: SPARK | M14: Decan | O14: Decan Planets
K15: =IFERROR(VLOOKUP(E15&"-"&G15, Degree_Spark_DataBase[[Helper]:[Decan Planets]], 2, 0),"Not Found") -> Not Found | M15: =IFERROR(VLOOKUP(E15&"-"&G15, Degree_Spark_DataBase[[Helper]:[Decan Planets]], 3, 0),"Not Found") -> Not Found | O15: =IFERROR(VLOOKUP(E15&"-"&G15, Degree_Spark_DataBase[[Helper]:[Decan Planets]], 4, 0),"Not Found") -> Not Found

Sheet TruePlacement_calculator
B2: True Placement
C5: 1 house ruler | F5: 2 house rulers
B6: PLANET | C6: JUPITER | E6: PLANET | F6: VENUS
B7: SIGN | C7: Aquarius | E7: SIGN | F7: Sagittarius
B8: RISING | C8: Sagittarius | E8: RISING | F8: Sagittarius
F11: NEPTUNE in Sagittaruis (Sagittarius rising) | J11: house | M11: sign | O11: house | R11: sign
C12: =C6 -> JUPITER | E12: 1 | F12: =C6&" in "&C7&" ("&C8&" rising)" -> JUPITER in Aquarius (Sagittarius rising) | I12: is | J12: =IFERROR(VLOOKUP(C6&"-"&C7&"-"&C8, TruePlacement_DataBase1[[Helper]:[Sign3]], 3,FALSE), "") -> Gemini | K12: =IFERROR("("&VLOOKUP(C6&"-"&C7&"-"&C8, TruePlacement_DataBase1[[Helper]:[Sign3]], 2,FALSE)&")", "") -> (3rd) | L12: expressing through | M12: =IFERROR(VLOOKUP(C6&"-"&C7&"-"&C8, TruePlacement_DataBase1[[Helper]:[Sign3]], 4,FALSE),"") -> Aquarius | N12: with base from | O12: =IFERROR(VLOOKUP(C6&"-"&C7&"-"&C8, TruePlacement_DataBase1[[Helper]:[Sign3]], 5,FALSE), "") -> 1st | P12: =IFERROR(VLOOKUP(C6&"-"&C7&"-"&C8, TruePlacement_DataBase1[[Helper]:[Sign3]], 6,FALSE), "") -> Aries | Q12: expressing through | R12: =IFERROR(VLOOKUP(C6&"-"&C7&"-"&C8, TruePlacement_DataBase1[[Helper]:[Sign3]], 7,FALSE), "") -> Sagittarius
C15: =F6 -> VENUS | E15: 2 | F15: =F6&" in "&F7&" ("&F8&" rising)" -> VENUS in Sagittarius (Sagittarius rising) | I15: is | J15: =IFERROR(VLOOKUP(F6&"-"&F7&"-"&F8, TruePlacement_DataBase2[[Helper]:[Sign5]], 3,0), "") -> Aries | K15: =IFERROR("("&VLOOKUP(F6&"-"&F7&"-"&F8, TruePlacement_DataBase2[[Helper]:[Sign5]], 2,0)&")", "") -> (1st) | L15: expressing through | M15: =IFERROR(VLOOKUP(F6&"-"&F7&"-"&F8, TruePlacement_DataBase2[[Helper]:[Sign5]], 4,0), "") -> Sagittarius | N15: with base from | O15: =IFERROR(VLOOKUP(F6&"-"&F7&"-"&F8, TruePlacement_DataBase2[[Helper]:[Sign5]], 5,0), "") -> 6th | P15: =IFERROR(VLOOKUP(F6&"-"&F7&"-"&F8, TruePlacement_DataBase2[[Helper]:[Sign5]], 6,0), "") -> Virgo | Q15: expressing through | R15: =IFERROR(VLOOKUP(F6&"-"&F7&"-"&F8, TruePlacement_DataBase2[[Helper]:[Sign5]], 7,0), "") -> Taurus | S15: and | T15: =IFERROR(VLOOKUP(F6&"-"&F7&"-"&F8, TruePlacement_DataBase2[[Helper]:[Sign5]], 8,0), "") -> 11th | U15: =IFERROR(VLOOKUP(F6&"-"&F7&"-"&F8, TruePlacement_DataBase2[[Helper]:[Sign5]], 9,0), "") -> Aquarius | V15: expressing through | W15: =IFERROR(VLOOKUP(F6&"-"&F7&"-"&F8, TruePlacement_DataBase2[[Helper]:[Sign5]], 10,0), "") -> Libra

Sheet Practice
L2: NEPTUNE | M2: is | N2: Sagittarius | O2: in | P2: Sagittarius spark | Q2: in | R2: Sagittarius decan | S2: expressing through | T2: Sagittarius | U2: with | V2: Sagittarius | W2: and Neptune | X2: base | AI2: DATA-do not touch | AV2: 1 | AW2: 2
L3: PLANET | N3: HOUSE | P3: SPARK | R3: DECAN | T3: SIGN | V3: HOUSE | AH3: 1 | AJ3: is | AK3: =IFERROR("("&VLOOKUP(C5&"-"&E5&"-"&I5, TruePlacement_DataBase1[[Helper]:[Sign3]], 2,FALSE)&")", "") -> (1st) | AL3: =IFERROR(VLOOKUP(C5&"-"&E5&"-"&I5, TruePlacement_DataBase1[[Helper]:[Sign3]], 3,FALSE), "") -> Aries | AM3: ET | AN3: =IFERROR(VLOOKUP(C5&"-"&E5&"-"&I5, TruePlacement_DataBase1[[Helper]:[Sign3]], 4,FALSE), "") -> Sagittarius | AO3: with base from | AP3: =IFERROR(VLOOKUP(C5&"-"&E5&"-"&I5, TruePlacement_DataBase1[[Helper]:[Sign3]], 5,FALSE), "") -> 9th | AQ3: =IFERROR(VLOOKUP(C5&"-"&E5&"-"&I5, TruePlacement_DataBase1[[Helper]:[Sign3]], 6,FALSE), "") -> Sagittarius | AR3: expressing through | AS3: =IFERROR(VLOOKUP(C5&"-"&E5&"-"&I5, TruePlacement_DataBase1[[Helper]:[Sign3]], 7,FALSE), "") -> Leo | AV3: BASE sign
B5: Planet: | C5: SUN | D5: Sign: | E5: Sagittarius | F5: Degree: | G5: 20° | H5: Rising: | I5: Sagittarius | L5: =C5 -> SUN | M5: is | N5: =IFERROR(VLOOKUP(C5&"-"&E5&"-"&I5, TruePlacement_DataBase1[[#All],[Helper]:[Sign6]], 3, 0), "") -> Aries | O5: in | P5: =IFERROR(VLOOKUP(G5&"-"&E5, Degree_Spark_DataBase[[Helper]:[Decan Planets]], 2, 0)&" spark","") -> Sagittarius spark | Q5: in | R5: =IFERROR(VLOOKUP(G5&"-"&E5, Degree_Spark_DataBase[[Helper]:[Decan Planets]], 3, 0)&" decan","Not Found") -> Leo decan | S5: expressing through | T5: =IFERROR(VLOOKUP(C5&"-"&E5&"-"&I5, TruePlacement_DataBase1[[Helper]:[Sign3]], 4,FALSE), "") -> Sagittarius | U5: with | V5: =IFERROR(VLOOKUP(C5&"-"&E5&"-"&I5, TruePlacement_DataBase1[[Helper]:[Sign3]], 6,FALSE), "") -> Sagittarius | W5: =IFERROR("and "&VLOOKUP(C5&"-"&E5&"-"&I5, TruePlacement_DataBase1[[Helper]:[Sign6]], 9,FALSE), "") -> and | X5: base | AH5: 2 | AJ5: is | AL5: in | AN5: in | AP5: expressing through | AR5: with | AU5: base
P6: =IFERROR(VLOOKUP(G5&"-"&E5, Degree_Spark_DataBase[[Helper]:[Decan Planets]], 2, 0),"spark") -> Sagittarius | R6: =IFERROR(VLOOKUP(G5&"-"&E5, Degree_Spark_DataBase[[Helper]:[Decan Planets]], 3, 0),"decan") -> Leo | V6: =IFERROR(VLOOKUP(C5&"-"&E5&"-"&I5, TruePlacement_DataBase1[[Helper]:[Sign3]], 6,FALSE), "") -> Sagittarius | W6: =IFERROR(VLOOKUP(C5&"-"&E5&"-"&I5, TruePlacement_DataBase1[[Helper]:[Sign6]], 9,FALSE), "") -> 0
V7: =IFERROR(VLOOKUP(C5&"-"&E5&"-"&I5, TruePlacement_DataBase1[[Helper]:[Sign5]], 7,0), "") -> Leo | W7: =IFERROR(VLOOKUP(C5&"-"&E5&"-"&I5, TruePlacement_DataBase1[[Helper]:[Sign6]], 10,0), "") -> 0
C12: PLANET | F12: HOUSE | I12: SIGN | L12: HOUSE | Q12: SIGN
C13: =L5 -> SUN | F13: =V5 -> Sagittarius | I13: =V7 -> Leo | L13: =N5 -> Aries | Q13: =T5 -> Sagittarius
C15: Existence | E15: based on | F15: Philosophy | H15: through | I15: Purpose | K15: directed into | L15: Action | O15: expressed through | Q15: Coaching
C18: SPARK
C19: =P6 -> Sagittarius | I19: =C15&" "&E15&" "&F15&" "&H15&" "&I15&" "&K15&" "&L15&" "&O15&" "&Q15 -> Existence based on Philosophy through Purpose directed into Action expressed through Coaching
C21: DECAN
C22: =R6 -> Leo
C25: Your sentence: | Z25: =AB30&" is "&AB31&", with "&AB32&" spark in "&AB33&" decan, expressed through "&AB34&" with "&AB35&" base (through "&AB36&")" -> SUN is Aries, with Sagittarius spark in Leo decan, expressed through Sagittarius with Sagittarius base (through Leo)
Z26: =AB30&" is "&AB31&", with "&AB32&" spark in "&AB33&" decan, expressed through "&AB34&" with "&AB35&" and "&AB37&" base (through "&AB36&" and "&AB38&")" -> SUN is Aries, with Sagittarius spark in Leo decan, expressed through Sagittarius with Sagittarius and 0 base (through Leo and 0)
AA30: Planet: | AB30: =L5 -> SUN
AA31: is: | AB31: =N5 -> Aries
AA32: Spark: | AB32: =P6 -> Sagittarius
AA33: Decan: | AB33: =R6 -> Leo
AA34: expressed th: | AB34: =T5 -> Sagittarius
Z35: with base | AA35: house: | AB35: =V6 -> Sagittarius
AA36: sign: | AB36: =V7 -> Leo
Z37: 2nd base | AA37: house: | AB37: =W6 -> 0
AA38: sign: | AB38: =W7 -> 0
H48: THROUGH | I48: house | K48: AND | L48: sign | P48: THROUGH | Q48: sign | S48: DIRECTED INTO | T48: house | W48: EXPRESSED THROUGH | Y48: sign
C51: PLANET | F51: HOUSE | I51: SIGN | L51: HOUSE | Q51: SIGN | T51: HOUSE | Y51: SIGN
C52: =L5 -> SUN | F52: =V6 -> Sagittarius | I52: =V7 -> Leo | L52: =W6 -> 0 | Q52: =W7 -> 0 | T52: =N5 -> Aries | Y52: =T5 -> Sagittarius
C54: Identity (internal) | E54: based on | F54: The Devine Feminine | H54: through | I54: Ideas | K54: and | L54: Discipline | O54: through | Q54: Analytical Skills | S54: directed into | T54: Dance | W54: expressed through | Y54: Inner power
C57: SPARK
C58: =P6 -> Sagittarius
C60: DECAN
C61: =R6 -> Leo

Sheet Practice2
L2: NEPTUNE | M2: is | N2: Sagittarius | O2: in | P2: Sagittarius spark | Q2: in | R2: Sagittarius decan | S2: expressing through | T2: Sagittarius | U2: with | V2: Sagittarius | W2: and Neptune | X2: base
L3: PLANET | N3: HOUSE | P3: SPARK | R3: DECAN | T3: SIGN | V3: HOUSE
B5: Planet: | C5: URANUS | D5: Sign: | E5: Sagittarius | F5: Degree: | G5: 18° | H5: Rising: | I5: Sagittarius | L5: =C5 -> URANUS | M5: is | N5: =IFERROR(VLOOKUP(C5&"-"&E5&"-"&I5, TruePlacement_DataBase1[[#All],[Helper]:[Sign6]], 3, 0), "") -> Aries | O5: in | P5: =IFERROR(VLOOKUP(G5&"-"&E5, Degree_Spark_DataBase[[Helper]:[Decan Planets]], 2, 0)&" spark","") -> Libra spark | Q5: in | R5: =IFERROR(VLOOKUP(G5&"-"&E5, Degree_Spark_DataBase[[Helper]:[Decan Planets]], 3, 0)&" decan","Not Found") -> Aries decan | S5: expressing through | T5: =IFERROR(VLOOKUP(C5&"-"&E5&"-"&I5, TruePlacement_DataBase1[[Helper]:[Sign3]], 4,FALSE), "") -> Sagittarius | U5: with | V5: =IFERROR(VLOOKUP(C5&"-"&E5&"-"&I5, TruePlacement_DataBase1[[Helper]:[Sign3]], 6,FALSE), "") -> Gemini | W5: =IFERROR("and "&VLOOKUP(C5&"-"&E5&"-"&I5, TruePlacement_DataBase1[[Helper]:[Sign6]], 9,FALSE), "") -> and | X5: base
P6: =IFERROR(VLOOKUP(G5&"-"&E5, Degree_Spark_DataBase[[Helper]:[Decan Planets]], 2, 0),"spark") -> Libra | R6: =IFERROR(VLOOKUP(G5&"-"&E5, Degree_Spark_DataBase[[Helper]:[Decan Planets]], 3, 0),"decan") -> Aries | V6: =IFERROR(VLOOKUP(C5&"-"&E5&"-"&I5, TruePlacement_DataBase1[[Helper]:[Sign3]], 6,FALSE), "") -> Gemini | W6: =IFERROR(VLOOKUP(C5&"-"&E5&"-"&I5, TruePlacement_DataBase1[[Helper]:[Sign6]], 9,FALSE), "") -> 0
V7: =IFERROR(VLOOKUP(C5&"-"&E5&"-"&I5, TruePlacement_DataBase1[[Helper]:[Sign5]], 7,0), "") -> Aquarius | W7: =IFERROR(VLOOKUP(C5&"-"&E5&"-"&I5, TruePlacement_DataBase2[[Helper]:[Sign5]], 10,0), "")
E8: RULER
D9: 14° | E9: =IFERROR(VLOOKUP(E5, Ruler[], 2, 0), "") -> JUPITER | F9: in | G9: Aquarius
U10: =VLOOKUP(AB43, Seznami!O35:P36, 2, 0) -> URANUS is Aries, with Libra spark in Aries decan, expressed through Sagittarius with Gemini base (through Aquarius)
C12: PLANET | F12: HOUSE | I12: SIGN | L12: HOUSE | Q12: SIGN
C13: =L5 -> URANUS | F13: =V5 -> Gemini | I13: =V7 -> Aquarius | L13: =N5 -> Aries | Q13: =T5 -> Sagittarius
E15: based on | H15: through | K15: directed into | O15: expressed through
U17: =VLOOKUP(AG43, Seznami!O40:P41, 2, 0) -> JUPITER in Gemini, with Gemini spark in Gemini decan, expressed through Aquarius with Aries base (through Sagittarius)
C22: SPARK
C23: =P6 -> Libra | I23: =C15&" "&E15&" "&F15&" "&H15&" "&I15&" "&K15&" "&L15&" "&O15&" "&Q15 -> based on through directed into expressed through
Z24: RULER
C25: DECAN | Z25: =AG34&" in "&AG35&", with "&AG36&" spark in "&AG37&" decan, expressed through "&AG38&" with "&AG39&" base (through "&AG40&")" -> JUPITER in Gemini, with Gemini spark in Gemini decan, expressed through Aquarius with Aries base (through Sagittarius)
C26: =R6 -> Aries | Z26: =AG34&" in "&AG35&", with "&AG36&" spark in "&AG37&" decan, expressed through "&AG38&" with "&AG39&" and "&AG41&" base (through "&AG40&" and "&AG42&")" -> JUPITER in Gemini, with Gemini spark in Gemini decan, expressed through Aquarius with Aries and 0 base (through Sagittarius and )
Z28: PLANET
C29: Your sentence: | Z29: =AB34&" is "&AB35&", with "&AB36&" spark in "&AB37&" decan, expressed through "&AB38&" with "&AB39&" base (through "&AB40&")" -> URANUS is Aries, with Libra spark in Aries decan, expressed through Sagittarius with Gemini base (through Aquarius)
Z30: =AB34&" is "&AB35&", with "&AB36&" spark in "&AB37&" decan, expressed through "&AB38&" with "&AB39&" and "&AB41&" base (through "&AB40&" and "&AB42&")" -> URANUS is Aries, with Libra spark in Aries decan, expressed through Sagittarius with Gemini and 0 base (through Aquarius and )
AA34: Planet: | AB34: =L5 -> URANUS | AF34: Planet: | AG34: =E9 -> JUPITER
AA35: is: | AB35: =N5 -> Aries | AF35: is: | AG35: =IFERROR(VLOOKUP(E9&"-"&G9&"-"&I5, TruePlacement_DataBase1[[#All],[Helper]:[Sign6]], 3, 0), "") -> Gemini
AA36: Spark: | AB36: =P6 -> Libra | AF36: Spark: | AG36: =IFERROR(VLOOKUP(D9&"-"&G9, Degree_Spark_DataBase[[Helper]:[Decan Planets]], 2, 0),"") -> Gemini
AA37: Decan: | AB37: =R6 -> Aries | AF37: Decan: | AG37: =IFERROR(VLOOKUP(D9&"-"&G9, Degree_Spark_DataBase[[Helper]:[Decan Planets]], 3, 0),"Not Found") -> Gemini
AA38: expressed th: | AB38: =T5 -> Sagittarius | AF38: expressed th: | AG38: =IFERROR(VLOOKUP(E9&"-"&G9&"-"&I5, TruePlacement_DataBase1[[Helper]:[Sign3]], 4,FALSE), "") -> Aquarius | AJ38: PLANET:
Z39: with base | AA39: house: | AB39: =V6 -> Gemini | AE39: with base | AF39: house: | AG39: =IFERROR(VLOOKUP(E9&"-"&G9&"-"&I5, TruePlacement_DataBase1[[Helper]:[Sign3]], 6,FALSE), "") -> Aries | AJ39: True Placement:
AA40: sign: | AB40: =V7 -> Aquarius | AF40: sign: | AG40: =IFERROR(VLOOKUP(E9&"-"&G9&"-"&I5, TruePlacement_DataBase1[[Helper]:[Sign5]], 7,0), "") -> Sagittarius | AJ40: Ruler:
Z41: 2nd base | AA41: house: | AB41: =W6 -> 0 | AE41: 2nd base | AF41: house: | AG41: =IFERROR(VLOOKUP(E9&"-"&G9&"-"&I5, TruePlacement_DataBase1[[Helper]:[Sign6]], 9, 0), "") -> 0 | AJ41: Sentence:
AA42: sign: | AB42: =W7 | AF42: sign: | AG42: =IFERROR(VLOOKUP(E9&"-"&G9&"-"&I5, TruePlacement_DataBase2[[Helper]:[Sign5]], 10,0), "")
AA43: Ruler: | AB43: =VLOOKUP(AB34,Seznami!N2:O12, 2, 0) -> 1 | AF43: Ruler: | AG43: =VLOOKUP(AG34,Seznami!N2:O12, 2, 0) -> 1
H53: THROUGH | I53: house | K53: AND | L53: sign | P53: THROUGH | Q53: sign | S53: DIRECTED INTO | T53: house | W53: EXPRESSED THROUGH | Y53: sign
C56: PLANET | F56: HOUSE | I56: SIGN | L56: HOUSE | Q56: SIGN | T56: HOUSE | Y56: SIGN
C57: =L5 -> URANUS | F57: =V6 -> Gemini | I57: =V7 -> Aquarius | L57: =W6 -> 0 | Q57: =W7 | T57: =N5 -> Aries | Y57: =T5 -> Sagittarius
C59: Identity (internal) | E59: based on | F59: The Devine Feminine | H59: through | I59: Ideas | K59: and | L59: Discipline | O59: through | Q59: Analytical Skills | S59: directed into | T59: Dance | W59: expressed through | Y59: Inner power
C62: SPARK
C63: =P6 -> Libra
C65: DECAN
C66: =R6 -> Aries

Sheet Practice3
L2: NEPTUNE | M2: is | N2: Sagittarius | O2: in | P2: Sagittarius spark | Q2: in | R2: Sagittarius decan | S2: expressing through | T2: Sagittarius | U2: with | V2: Sagittarius | W2: and Neptune | X2: base
L3: PLANET | N3: HOUSE | P3: SPARK | R3: DECAN | T3: SIGN | V3: HOUSE
B5: Planet: | D5: Sign: | F5: Degree: | H5: Rising: | L5: =C5 -> 0 | M5: is | N5: =IFERROR(VLOOKUP(C5&"-"&E5&"-"&I5, TruePlacement_DataBase1[[#All],[Helper]:[Sign6]], 3, 0), "") | O5: in | P5: =IFERROR(VLOOKUP(G5&"-"&E5, Degree_Spark_DataBase[[Helper]:[Decan Planets]], 2, 0)&" spark","") | Q5: in | R5: =IFERROR(VLOOKUP(G5&"-"&E5, Degree_Spark_DataBase[[Helper]:[Decan Planets]], 3, 0)&" decan","Not Found") -> Not Found | S5: expressing through | T5: =IFERROR(VLOOKUP(C5&"-"&E5&"-"&I5, TruePlacement_DataBase1[[Helper]:[Sign3]], 4,FALSE), "") | U5: with | V5: =IFERROR(VLOOKUP(C5&"-"&E5&"-"&I5, TruePlacement_DataBase1[[Helper]:[Sign3]], 6,FALSE), "") | W5: =IFERROR("and "&VLOOKUP(C5&"-"&E5&"-"&I5, TruePlacement_DataBase1[[Helper]:[Sign6]], 9,FALSE), "") | X5: base
P6: =IFERROR(VLOOKUP(G5&"-"&E5, Degree_Spark_DataBase[[Helper]:[Decan Planets]], 2, 0),"spark") -> spark | R6: =IFERROR(VLOOKUP(G5&"-"&E5, Degree_Spark_DataBase[[Helper]:[Decan Planets]], 3, 0),"decan") -> decan | V6: =IFERROR(VLOOKUP(C5&"-"&E5&"-"&I5, TruePlacement_DataBase1[[Helper]:[Sign3]], 6,FALSE), "") | W6: =IFERROR(VLOOKUP(C5&"-"&E5&"-"&I5, TruePlacement_DataBase1[[Helper]:[Sign6]], 9,FALSE), "")
V7: =IFERROR(VLOOKUP(C5&"-"&E5&"-"&I5, TruePlacement_DataBase1[[Helper]:[Sign5]], 7,0), "") | W7: =IFERROR(VLOOKUP(C5&"-"&E5&"-"&I5, TruePlacement_DataBase2[[Helper]:[Sign5]], 10,0), "")
E8: RULER
E9: =IFERROR(VLOOKUP(E5, Ruler[], 2, 0), "") | F9: in
U10: =VLOOKUP(AG50, Seznami!O52:P53, 2, 0) -> #N/A
C12: PLANET | F12: HOUSE | I12: SIGN | L12: HOUSE | Q12: SIGN
C13: =L5 -> 0 | F13: =V5 | I13: =V7 | L13: =N5 | Q13: =T5
E15: based on | H15: through | K15: directed into | O15: expressed through
U17: =VLOOKUP(AM50, Seznami!O57:P58, 2, 0) -> #N/A
C22: SPARK | AF22: =I5&" rising with "&C5&" in "&E5&" at "&G5 -> rising with in at
C23: =P6 -> spark | Q23: =C15&" "&E15&" "&F15&" "&H15&" "&I15&" "&K15&" "&L15&" "&O15&" "&Q15 -> based on through directed into expressed through
AE24: RULER
C25: DECAN | H25: going into | AE25: =AM41&" in "&AM42&", with "&AM43&" spark in "&AM44&" decan, expressed through "&AM45&" with "&AM46&" base (through "&AM47&")" -> in , with spark in Not Found decan, expressed through with base (through )
C26: =R6 -> decan | AE26: =AM41&" in "&AM42&", with "&AM43&" spark in "&AM44&" decan, expressed through "&AM45&" with "&AM46&" and "&AM48&" base (through "&AM47&" and "&AM49&")" -> in , with spark in Not Found decan, expressed through with and base (through and )
J27: Ruler: | L27: =E9
J28: is: | L28: =IFERROR(VLOOKUP(E9&"-"&G9&"-"&I5, TruePlacement_DataBase1[[#All],[Helper]:[Sign6]], 3, 0), "") | Q28: =Q23&" going into "&N28&" (with "&N29&" and "&N30&"), expressed through "&N31&"." -> based on through directed into expressed through going into (with and ), expressed through .
J29: Spark: | L29: =IFERROR(VLOOKUP(D9&"-"&G9, Degree_Spark_DataBase[[Helper]:[Decan Planets]], 2, 0),"")
J30: Decan: | L30: =IFERROR(VLOOKUP(D9&"-"&G9, Degree_Spark_DataBase[[Helper]:[Decan Planets]], 3, 0),"Not Found") -> Not Found
J31: express: | L31: =IFERROR(VLOOKUP(E9&"-"&G9&"-"&I5, TruePlacement_DataBase1[[Helper]:[Sign3]], 4,FALSE), "")
AE35: PLANET
C36: Your sentence: | AE36: =AG41&" is "&AG42&", with "&AG43&" spark in "&AG44&" decan, expressed through "&AG45&" with "&AG46&" base (through "&AG47&")" -> 0 is , with spark spark in decan decan, expressed through with base (through )
AE37: =AG41&" is "&AG42&", with "&AG43&" spark in "&AG44&" decan, expressed through "&AG45&" with "&AG46&" and "&AG48&" base (through "&AG47&" and "&AG49&")" -> 0 is , with spark spark in decan decan, expressed through with and base (through and )
AE40: PLANET | AK40: RULER
AF41: Planet: | AG41: =L5 -> 0 | AL41: Planet: | AM41: =E9
AF42: is: | AG42: =N5 | AL42: is: | AM42: =IFERROR(VLOOKUP(E9&"-"&G9&"-"&I5, TruePlacement_DataBase1[[#All],[Helper]:[Sign6]], 3, 0), "")
AF43: Spark: | AG43: =P6 -> spark | AL43: Spark: | AM43: =IFERROR(VLOOKUP(D9&"-"&G9, Degree_Spark_DataBase[[Helper]:[Decan Planets]], 2, 0),"")
AF44: Decan: | AG44: =R6 -> decan | AL44: Decan: | AM44: =IFERROR(VLOOKUP(D9&"-"&G9, Degree_Spark_DataBase[[Helper]:[Decan Planets]], 3, 0),"Not Found") -> Not Found
AF45: expressed th: | AG45: =T5 | AL45: expressed th: | AM45: =IFERROR(VLOOKUP(E9&"-"&G9&"-"&I5, TruePlacement_DataBase1[[Helper]:[Sign3]], 4,FALSE), "") | AR45: PLANET: | AS45: =AF22 -> rising with in at
AE46: with base | AF46: house: | AG46: =V6 | AK46: with base | AL46: house: | AM46: =IFERROR(VLOOKUP(E9&"-"&G9&"-"&I5, TruePlacement_DataBase1[[Helper]:[Sign3]], 6,FALSE), "") | AR46: True Placement: | AS46: =U10 -> #N/A
AF47: sign: | AG47: =V7 | AL47: sign: | AM47: =IFERROR(VLOOKUP(E9&"-"&G9&"-"&I5, TruePlacement_DataBase1[[Helper]:[Sign5]], 7,0), "") | AR47: Ruler: | AS47: =U17 -> #N/A
AE48: 2nd base | AF48: house: | AG48: =W6 | AK48: 2nd base | AL48: house: | AM48: =IFERROR(VLOOKUP(E9&"-"&G9&"-"&I5, TruePlacement_DataBase1[[Helper]:[Sign6]], 9, 0), "") | AR48: Sentence1: | AS48: =Q23 -> based on through directed into expressed through
AF49: sign: | AG49: =W7 | AL49: sign: | AM49: =IFERROR(VLOOKUP(E9&"-"&G9&"-"&I5, TruePlacement_DataBase2[[Helper]:[Sign5]], 10,0), "") | AR49: Sentence2: | AS49: =Q28 -> based on through directed into expressed through going into (with and ), expressed through .
AF50: Ruler: | AG50: =VLOOKUP(AG41,Seznami!N2:O12, 2, 0) -> #N/A | AL50: Ruler: | AM50: =VLOOKUP(AM41,Seznami!N2:O12, 2, 0) -> #N/A
AS51: =AS45 -> rising with in at
AS52: =AB70 -> #N/A
AS53: =AB77 -> #N/A
AS54: =Q70 -> based on ( and ) through ( and ) directed into expressed through
...

Sheet WORD_document
A1: PLANET | B1: True Placement: | C1: Ruler | D1: Sentence1 | E1: Sentence2
A2: Sagittarius rising with MERCURY in Scorpio at 29° | B2: MERCURY is Pisces, with Pisces spark in Cancer decan, expressed through Scorpio with Libra and Capricorn base (through Gemini and Virgo) | C2: PLUTO in Pisces, with Sagittarius spark in Scorpio decan, expressed through Scorpio with Pisces base (through Scorpio) | D2: Mindset based on (Beauty and Career (what field)) through (Communication and Efficiency) directed into Inspiration expressed through Power. | E2: Mindset based on (Beauty and Career (what field)) through (Communication and Efficiency) directed into Inspiration expressed through Power. going into Creativity (with Culture and Psychology), expressed through Crime & Mystery.
A3: Sagittarius rising with MARS in Libra at 28° | B3: MARS is Aquarius, with Leo spark in Gemini decan, expressed through Libra with Leo base (through Aries) | C3: VENUS in Aries, with Pisces spark in Aries decan, expressed through Sagittarius with Virgo and Aquarius base (through Taurus and Libra) | D3: Action based on Happiness through Challenge directed into Community expressed through Books (reading) | E3: Action based on Happiness through Challenge directed into Community expressed through Books (reading) going into Drive (with Creativity and Movement), expressed through Opportunity.
A4: Sagittarius rising with URANUS in Sagittarius at 18° | B4: URANUS is Aries, with Libra spark in Aries decan, expressed through Sagittarius with Gemini base (through Aquarius) | C4: JUPITER in Gemini, with Gemini spark in Gemini decan, expressed through Aquarius with Aries base (through Sagittarius) | D4: based on through directed into expressed through

Sheet row_WD
A1: Sagittarius rising with MERCURY in Scorpio at 29° | B1: MERCURY is Pisces, with Pisces spark in Cancer decan, expressed through Scorpio with Libra and Capricorn base (through Gemini and Virgo) | C1: PLUTO in Pisces, with Sagittarius spark in Scorpio decan, expressed through Scorpio with Pisces base (through Scorpio) | D1: Mindset based on (Beauty and Career (what field)) through (Communication and Efficiency) directed into Inspiration expressed through Power. | E1: Mindset based on (Beauty and Career (what field)) through (Communication and Efficiency) directed into Inspiration expressed through Power. going into Creativity (with Culture and Psychology), expressed through Crime & Mystery.

Sheet List5
D3: PLANET | F3: HOUSE(sign) | H3: SIGN(of the house) | J3: HOUSE | L3: SIGN
D4: =TruePlacement_calculator!C12 -> JUPITER | F4: =TruePlacement_calculator!P12 -> Aries | H4: =TruePlacement_calculator!R12 -> Sagittarius | J4: =TruePlacement_calculator!J12 -> Gemini | L4: =TruePlacement_calculator!M12 -> Aquarius
E6: based on | G6: through | I6: directed into | K6: expressed through
E8: Spark
E10: Decan
D15: PLANET | F15: HOUSE(sign) | H15: SIGN(of the house) | J15: HOUSE(sign) | L15: SIGN(of the house) | N15: HOUSE | P15: SIGN
D16: =TruePlacement_calculator!C15 -> VENUS | F16: =TruePlacement_calculator!P15 -> Virgo | H16: =TruePlacement_calculator!R15 -> Taurus | J16: =TruePlacement_calculator!U15 -> Aquarius | L16: =TruePlacement_calculator!W15 -> Libra | N16: =TruePlacement_calculator!J15 -> Aries | P16: =TruePlacement_calculator!M15 -> Sagittarius
D18: Art | E18: based on | F18: Cycles | G18: through | H18: Comfort | I18: AND | J18: Action | K18: through | L18: Beauty | M18: directed into | N18: Authority | O18: expressed through | P18: Home Life
C20: Pisces | E20: Spark
C22: Cancer | E22: Decan

Sheet List8
E3: PLANET | G3: HOUSE(sign) | I3: SIGN(of the house) | K3: HOUSE | M3: SIGN
E4: SUN | G4: Aries | I4: Sagittarius
E5: Character | F5: based on | H5: through | J5: directed into | L5: expressed through
B8: RULER:
B9: Spark:
B10: Decan: | N10: Intuition based on feelings and mood through dreams directed into internal comfort expressed through accomplishment | W10: Intuition is based on emotions and dreams, leading to personal comfort and accomplishment. Intuition based on dreams can lead to inward comfort and accomplishment. Intuition through dreams can lead to inward comfort and accomplishment.
B11: BASED ON:
B12: THROUGH:
B13: BASED ON:
B14: THROUGH: | N14: Action based on core personality through direct personal energy directed into breakthrough expressed through design | W14: Personal energy is devoted on achieving breakthroughs through design, reflecting inner personality. Using personal energy to achieve breakthroughs through design, based on core personality. Personal energy is directed towards breakthroughs through design, based on key personality traits. | AF14: Your statement highlights the importance of harnessing one's core personality and personal energy to create breakthrough innovations through design. By channeling authentic self-expression and intrinsic motivations into the design process, you can foster unique, impactful solutions that resonate deeply and drive meaningful progress. This approach emphasizes the power of self-awareness and energetic authenticity as catalysts for breakthrough creativity in design. | AS14: The text emphasizes that leveraging one's core personality and authentic energy in the design process can lead to innovative and impactful solutions, with self-awareness and authenticity serving as key drivers of creative breakthroughs.
N18: Identity (internal) based on The Devine Feminine through Ideas and Discipline through Analytical Skills directed into Dance expressed through Inner power | W18: Your internal identity is rooted in the Divine Feminine, which channels ideas and discipline through analytical skills, ultimately directing your energy into dance as a form of expression, showcasing your inner power.
E47: Sagittarius rising with MERCURY in Scorpio at 29°
E48: MERCURY is Pisces, with Pisces spark in Cancer decan, expressed through Scorpio with Libra and Capricorn base (through Gemini and Virgo)
E49: PLUTO in Pisces, with Sagittarius spark in Scorpio decan, expressed through Scorpio with Pisces base (through Scorpio)
E50: MERCURY is Pisces, with Pisces spark in Cancer decan, expressed through Scorpio with Libra and Capricorn base (through Gemini and Virgo)
E51: PLUTO in Pisces, with Sagittarius spark in Scorpio decan, expressed through Scorpio with Pisces base (through Scorpio)

Sheet ListOption_PLANET
A1: List option
A3: Planet | B3: MOON | C3: SUN | D3: VENUS | E3: MERCURY | F3: MARS | G3: PLUTO | H3: JUPITER | I3: SATURN | J3: URANUS | K3: NEPTUNE
A4: MOON | B4: Agriculture | C4: Amusement | D4: Art | E4: Business name (S+H+P) | F4: Action | G4: Abuse | H4: Abundance | I4: Achievement | J4: Accounting | K4: Alcoholism
A5: SUN | B5: Ancestry | C5: Appreciation | D5: Beauty | E5: Classmates - early education | F5: Aggression | G5: Borrowing and landing money | H5: Accumulation | I5: Accomplishment | J5: Activism | K5: Background
A6: VENUS | B6: Bedroom | C6: Celebration | D6: Books | E6: Close / local environment | F6: Assertion | G6: Change | H6: Adventure | I6: Age | J6: Aliens | K6: BTS
A7: MERCURY | B7: Caring | C7: Character | D7: Comfort | E7: Communication | F7: Beginnings | G7: Confinement | H7: Advertising & Marketing | I7: Authority | J7: Alternative Lifestyle | K7: Closing of cycles
A8: MARS | B8: Domestication | C8: Children | D8: Dairy | E8: Cousins | F8: Blood | G8: Crime & Mystery | H8: Beliefs | I8: Best | J8: Astrology | K8: Compassion & Charity
A9: PLUTO | B9: Emotional Attachment | C9: Confidence | D9: Finance | E9: Coworkers | F9: Bravery | G9: Cycles | H9: Big Picture | I9: Bones | J9: Automation | K9: Confinement
A10: JUPITER | B10: Emotional Responses | C10: Core Personality | D10: Food | E10: Curiosity | F10: Challenge | G10: Darkness | H10: Coaching | I10: Bosses | J10: Aviation & Flying | K10: Connection to God
A11: SATURN | B11: Emotional Security | C11: Courage | D11: Fuel | E11: Data collecting | F11: Competition | G11: Debt | H11: Consulting | I11: Boundaries & Limits | J11: Breakthrough | K11: Creativity
A12: URANUS | B12: Emotions | C12: Creative Expression | D12: Herbs | E12: Early | F12: Conflict | G12: Decay & Poop | H12: Culture | I12: Career (what field) | J12: Clubs | K12: Dance
A13: NEPTUNE | B13: Empathy | C13: Ego | D13: Internal comfort | E13: Ears | F13: Courage | G13: Deep Bonds | H13: Distance | I13: Celebrities | J13: Community | K13: Delusion
B14: Fears | C14: Existence | D14: Items | E14: Eyes & Hands | F14: Devine Masculine | G14: Deep Healing | H14: Dramatics | I14: Consequence | J14: Detachment | K14: Disappearing
B15: Feelings & Mood | C15: Expression | D15: Luxury | E15: Fact & Figures | F15: Direct personal energy | G15: Depth | H15: Ethics & Morality | I15: Construction | J15: Dreams (future) | K15: Dissolutions
B16: Female Fertility | C16: Father | D16: Material Goods | E16: Hands | F16: Drive | G16: Dust & Debris | H16: Expansion | I16: Physical Structures | J16: Electricity & Technology | K16: Dreams
B17: Foundations | C17: Father Figures | D17: Milk | E17: Ideas | F17: Emergency & Urgency | G17: Erotic | H17: Experience | I17: Corporations | J17: Elevation | K17: Escapism
B18: Headquarters | C18: Fertility | D18: Mineral | E18: Identity (internal) | F18: Energy | G18: Inheritance | H18: Exploration | I18: Dedication | J18: Engineering | K18: Fantasy
B19: Home Life | C19: Fitness | D19: Money | E19: Learning | F19: First | G19: Inner Drive | H19: Exploration & Adventure | I19: Delays | J19: Erratic | K19: Fear
B20: Homeland & Country | C20: Fun | D20: Nature | E20: Learning Style | F20: Force | G20: Inner power | H20: Foreign | I20: Discipline | J20: Forward Thinking | K20: Feet
B21: Hometown | C21: Gambling | D21: Neck | E21: Local | F21: Head | G21: Intimacy | H21: Foreign Dealings | I21: Elders | J21: Freedom | K21: Film
B22: House & Home | C22: Happiness | D22: Physical Products | E22: Logic | F22: Impact | G22: Investigation | H22: Growth | I22: Endurance | J22: Friends groups | K22: Fluidity
B23: Inner Peace | C23: Heat | D23: Plants | E23: Mental Processes | F23: Impulse | G23: Jealousy | H23: Higer Education & College | I23: Focus | J23: Future | K23: Fog & Mist
B24: Instincts | C24: Hobbies | D24: Possessions | E24: Messages & Docs | F24: Independence | G24: Joint Ventures | H24: Higer Learning | I24: Formula (in math) | J24: Genius | K24: Haze & Confusion
B25: Intuition | C25: Inner Child | D25: Relaxation | E25: Mind (inner) | F25: Initiation | G25: Kinks | H25: Hips | I25: Goals | J25: Groups & Teams | K25: Hospitals
... B39: Soul | C39: Vitality | D39: Beauty | E39: Writing | F39: Violence | G39: Reproduction | H39: Optimism | I39: Patience | J39: Originality & Invention | K39: Music & Media
B40: Subconscious | C40: Willpower | D40: Books (reading) | E40: Analytical Skills | G40: Reproductive | H40: Overindulgence | I40: Perseverance | J40: Outcast & Outsider | K40: Painting
B41: Upbringing | C41: Young Age | D41: Business | E41: Analyzation | G41: Secrecy | H41: Philosophy | I41: Professionalism | J41: Progressivism | K41: Photography & Pictures
B42: Stomach | C42: Royalty | D42: Connecting to others | E42: Chores | G42: Secrets | H42: Place in the world | I42: Public image | J42: Questions | K42: Psychic Abilities
B43: Gut feeling (something doesn’t feel right) | C43: Actor | D43: Connection | E43: Critical Thinking | G43: Shared Resources | H43: Politics | I43: Regulations | J43: Quick change | K43: Psychic Connection
B44: Natural instinct | C44: Spotlight | D44: Conversation | E44: Criticism | G44: Tattoos | H44: Prospective | I44: Reputation | J44: Randomness | K44: Reflections
B45: Rip cage | C45: Drama | D45: Creative talents | E45: Critique | G45: Taxes | H45: Religion | I45: Respect | J45: Rebellion | K45: Sacrifice
B46: Habits (South NODE – your default system) | C46: Play | D46: Decor | E46: Day to Day | G46: Therapy | H46: Seeking Knowladge | I46: Responsibility | J46: Revolution | K46: Sensitivity
B47: Memory | C47: Games | D47: Design | E47: Details | G47: Things hidden | H47: Story | I47: Restrictions | J47: Science | K47: Spiritualism
B48: Sentimental security | C48: Life | D48: Diplomacy | E48: Efficiency | G48: Transformation | H48: Storytelling | I48: Rules | J48: Small Organizations | K48: Spirituality
B49: Farming | C49: Exist | D49: Elegance | E49: Employee(s) | G49: Trauma | H49: Teaching | I49: Skin | J49: Social events | K49: Substances
B50: Planting seeds | C50: Personal Creative Expression | D50: Equality | E50: Fitness | G50: Trust | H50: Thighs | I50: Spine | J50: Social Media | K50: Unconscious
B51: Working the ground | C51: Alive | D51: Fashion | E51: Healing Nutrition | G51: Willpower | H51: What ifs | I51: Structure | J51: Sudden Change | K51: Undoing
B52: Tenderness, Sadness, Nostalgia | C52: Childhood | D52: Glamour | E52: Health | H52: Wisdom | I52: Superiors | J52: Teams | K52: Unknown
B53: Grandmothers (more mother) | C53: Youth | D53: Grace | E53: Job | H53: Overwhelming | I53: System | J53: Technology | K53: Viruses
C54: Express | D54: Harmoney | E54: Logic | H54: Global | I54: Teacher | J54: Unconventional | K54: Water
...

Sheet ListOption_SIGN
A1: List option
A3: SIGN | B3: Aries | C3: Taurus | D3: Gemini | E3: Cancer | F3: Leo | G3: Virgo | H3: Libra | I3: Scorpio | J3: Sagittarius | K3: Capricorn | L3: Aquarius | M3: Pisces
A4: Aries | B4: Action | C4: Art | D4: Business name (S+H+P) | E4: Agriculture | F4: Amusement | G4: Analytical Skills | H4: Aesthetics | I4: Abuse | J4: Abundance | K4: Achievement | L4: Accounting | M4: Alcoholism
A5: Taurus | B5: Aggression | C5: Beauty | D5: Classmates - early education | E5: Ancestry | F5: Appreciation | G5: Analyzation | H5: Balance | I5: Borrowing and landing money | J5: Accumulation | K5: Accomplishment | L5: Activism | M5: Background
A6: Gemini | B6: Assertion | C6: Book | D6: Close / local environment | E6: Bedroom | F6: Celebration | G6: Chores | H6: Beauty | I6: Change | J6: Adventure | K6: Age | L6: Aliens | M6: BTS
A7: Cancer | B7: Beginnings | C7: Comfort | D7: Communication | E7: Caring | F7: Character | G7: Critical Thinking | H7: Books (reading) | I7: Confinement | J7: Advertising & Marketing | K7: Authority | L7: Alternative Lifestyle | M7: Closing of cycles
A8: Leo | B8: Blood | C8: Dairy | D8: Cousins | E8: Domestication | F8: Children | G8: Criticism | H8: Business | I8: Crime & Mystery | J8: Beliefs | K8: Best | L8: Astrology | M8: Compassion & Charity
A9: Virgo | B9: Bravery | C9: Finance | D9: Coworkers | E9: Emotional Attachment | F9: Confidence | G9: Critique | H9: Connecting to others | I9: Cycles | J9: Big Picture | K9: Bones | L9: Automation | M9: Confinement
A10: Libra | B10: Challenge | C10: Food | D10: Curiosity | E10: Emotional Responses | F10: Core Personality | G10: Day to Day | H10: Connection | I10: Darkness | J10: Coaching | K10: Bosses | L10: Aviation & Flying | M10: Connection to God
A11: Scorpio | B11: Competition | C11: Fuel | D11: Data collecting | E11: Emotional Security | F11: Courage | G11: Details | H11: Conversation | I11: Debt | J11: Consulting | K11: Boundaries & Limits | L11: Breakthrough | M11: Creativity
A12: Sagittarius | B12: Conflict | C12: Herbs | D12: Early | E12: Emotions | F12: Creative Expression | G12: Efficiency | H12: Creative talents | I12: Decay & Poop | J12: Culture | K12: Career (what field) | L12: Clubs | M12: Dance
A13: Capricorn | B13: Courage | C13: Internal comfort | D13: Ears | E13: Empathy | F13: Ego | G13: Employee(s) | H13: Decor | I13: Deep Bonds | J13: Distance | K13: Celebrities | L13: Community | M13: Delusion
A14: Aquarius | B14: Devine Masculine | C14: Items | D14: Eyes & Hands | E14: Fears | F14: Existence | G14: Fitness | H14: Design | I14: Deep Healing | J14: Dramatics | K14: Consequence | L14: Detachment | M14: Disappearing
A15: Pisces | B15: Direct personal energy | C15: Luxury | D15: Fact & Figures | E15: Feelings & Mood | F15: Expression | G15: Healing Nutrition | H15: Diplomacy | I15: Depth | J15: Ethics & Morality | K15: Construction | L15: Dreams (future) | M15: Dissolutions
B16: Drive | C16: Material Goods | D16: Hands | E16: Female Fertility | F16: Father | G16: Health | H16: Elegance | I16: Dust & Debris | J16: Expansion | K16: Physical Structures | L16: Electricity & Technology | M16: Dreams
B17: Emergency & Urgency | C17: Milk | D17: Ideas | E17: Foundations | F17: Father Figures | G17: Job | H17: Equality | I17: Erotic | J17: Experience | K17: Corporations | L17: Elevation | M17: Escapism
B18: Energy | C18: Mineral | D18: Identity (internal) | E18: Headquarters | F18: Fertility | G18: Logic | H18: Fashion | I18: Inheritance | J18: Exploration | K18: Dedication | L18: Engineering | M18: Fantasy
B19: First | C19: Money | D19: Learning | E19: Home Life | F19: Fitness | G19: Mind (outward) | H19: Glamour | I19: Inner Drive | J19: Exploration & Adventure | K19: Delays | L19: Erratic | M19: Fear
B20: Force | C20: Nature | D20: Learning Style | E20: Homeland & Country | F20: Fun | G20: Nervous System | H20: Grace | I20: Inner power | J20: Foreign | K20: Discipline | L20: Forward Thinking | M20: Feet
B21: Head | C21: Neck | D21: Local | E21: Hometown | F21: Gambling | G21: Nutrition | H21: Harmoney | I21: Intimacy | J21: Foreign Dealings | K21: Elders | L21: Freedom | M21: Film
B22: Impact | C22: Physical Products | D22: Logic | E22: House & Home | F22: Happiness | G22: Organization | H22: Hormones | I22: Investigation | J22: Growth | K22: Endurance | L22: Friends groups | M22: Fluidity
B23: Impulse | C23: Plants | D23: Mental Processes | E23: Inner Peace | F23: Heat | G23: Perfectionism | H23: Justice | I23: Jealousy | J23: Higer Education & College | K23: Focus | L23: Future | M23: Fog & Mist
B24: Independence | C24: Possessions | D24: Messages & Docs | E24: Instincts | F24: Hobbies | G24: Precision | H24: Legal Matters | I24: Joint Ventures | J24: Higer Learning | K24: Formula (in math) | L24: Genius | M24: Haze & Confusion
B25: Initiation | C25: Relaxation | D25: Mind (inner) | E25: Intuition | F25: Inner Child | G25: Reality | H25: Listening | I25: Kinks | J25: Hips | K25: Goals | L25: Groups & Teams | M25: Hospitals
B26: Movement | C26: Resources | D26: Mindset | E26: Land | F26: Joy | G26: Refinement | H26: Love | I26: Manipulation | J26: Hypotheticals | K26: Government | L26: Holistic | M26: Idealism
B27: Passion | C27: Self-Esteem | D27: Neighbours | E27: Mother & Family | F27: Leadership | G27: Routine | H27: Lungs | I27: Niche & Taboo | J27: Imagination | K27: Hierarchy | L27: Hopes | M27: Illness
... B34: Selfishness | C34: Value (self) | D34: Speaking | E34: Real Estate | F34: Recreation | G34: Work Environment | H34: Peace | I34: Psychology | J34: Luck | K34: Mentor | L34: Internet | M34: Jails / Prisons
B35: Sense of Self | C35: Values | D35: Thinking | E35: Response | F35: Rick | H35: Receiving | I35: Rage | J35: Meaning | K35: Milestone | L35: Lone Wolf | M35: Lies & Deception
B36: Sex drive | C36: Vanity | D36: Thoughts & Ideas | E36: Roots | F36: Romance | H36: Reciprocation | I36: Rebirth | J36: Mentorship | K36: Nails | L36: Mechanics | M36: Loss
B37: Speed | D37: Tools | E37: Safety | F37: Sport | H37: Relationship | I37: Regeneration | J37: Opinions | K37: Nose | L37: Networking | M37: Medical
B38: Spice | D38: Transport? | E38: Security | F38: Validation | H38: Sensual Pleasure | I38: Repeating the same cycles | J38: Opportunity | K38: Past Systems | L38: Objectivity | M38: Mental Illness
B39: Violence | D39: Writing | E39: Soul | F39: Vitality | H39: Sensuality | I39: Reproduction | J39: Optimism | K39: Patience | L39: Originality & Invention | M39: Music & Media
E40: Subconscious | F40: Willpower | H40: Style | I40: Reproductive | J40: Overindulgence | K40: Perseverance | L40: Outcast & Outsider | M40: Painting
E41: Upbringing | F41: Young Age | H41: Tact | I41: Secrecy | J41: Philosophy | K41: Professionalism | L41: Progressivism | M41: Photography & Pictures
E42: Stomach | F42: Royalty | H42: The Devine Feminine | I42: Secrets | J42: Place in the world | K42: Public image | L42: Questions | M42: Psychic Abilities
E43: Gut feeling (something doesn’t feel right) | F43: Actor | H43: Value (outward) | I43: Shared Resources | J43: Politics | K43: Regulations | L43: Quick change | M43: Psychic Connection
E44: Natural instinct | F44: Spotlight | I44: Tattoos | J44: Prospective | K44: Reputation | L44: Randomness | M44: Reflections
E45: Rip cage | F45: Drama | I45: Taxes | J45: Religion | K45: Respect | L45: Rebellion | M45: Sacrifice
E46: Habits (South NODE – your default system) | F46: Play | I46: Therapy | J46: Seeking Knowladge | K46: Responsibility | L46: Revolution | M46: Sensitivity
E47: Memory | F47: Games | I47: Things hidden | J47: Story | K47: Restrictions | L47: Science | M47: Spiritualism
...

Sheet Seznami
A2: Degree | C2: SIGN | E2: RISING SIGN | G2: SUBJECT | I2: TruePlacement2 | K2: Sign | L2: Ruler | N2: TruePlacement 1 | O2: Ruling
A3: 0° | C3: Aries | E3: Aries | G3: Sun | I3: VENUS | K3: Aries | L3: MARS | N3: MOON | O3: 1 | T3: MOON | W3: MARS
A4: 1° | C4: Taurus | E4: Taurus | G4: Moon | I4: MERCURY | K4: Taurus | L4: VENUS | N4: SUN | O4: 1 | T4: SUN | W4: VENUS
A5: 2° | C5: Gemini | E5: Gemini | G5: Venus | K5: Gemini | L5: MERCURY | N5: VENUS | O5: 2 | T5: VENUS | W5: MERCURY
A6: 3° | C6: Cancer | E6: Cancer | G6: Mercury | K6: Cancer | L6: MOON | N6: MERCURY | O6: 2 | T6: MERCURY | W6: MOON
A7: 4° | C7: Leo | E7: Leo | G7: Mars | K7: Leo | L7: SUN | N7: MARS | O7: 1 | T7: MARS | W7: SUN
A8: 5° | C8: Virgo | E8: Virgo | G8: Pluto | K8: Virgo | L8: MERCURY | N8: PLUTO | O8: 1 | T8: PLUTO | W8: PLUTO
A9: 6° | C9: Libra | E9: Libra | G9: Jupiter | K9: Libra | L9: VENUS | N9: JUPITER | O9: 1 | T9: JUPITER | W9: JUPITER
A10: 7° | C10: Scorpio | E10: Scorpio | G10: Saturn | K10: Scorpio | L10: PLUTO | N10: SATURN | O10: 1 | T10: SATURN | W10: SATURN
A11: 8° | C11: Sagittarius | E11: Sagittarius | G11: Uranus | K11: Sagittarius | L11: JUPITER | N11: URANUS | O11: 1 | T11: URANUS | W11: URANUS
A12: 9° | C12: Capricorn | E12: Capricorn | G12: Neptune | K12: Capricorn | L12: SATURN | N12: NEPTUNE | O12: 1 | T12: NEPTUNE | W12: NEPTUNE
A13: 10° | C13: Aquarius | E13: Aquarius | G13: ASC | K13: Aquarius | L13: URANUS
A14: 11° | C14: Pisces | E14: Pisces | G14: DSC | K14: Pisces | L14: NEPTUNE | V14: VLOOKUP(F6&"-"&F7&"-"&F8;
A15: 12° | G15: MC | V15: "("&VLOOKUP(F6&"-"&F7&"-"&F8; TruePlacement_DataBase2[[Helper]:[Sign5]]; 3;0)&")"
A16: 13° | G16: IC | V16: "("&VLOOKUP(C6&"-"&C7&"-"&C8; TruePlacement_DataBase1[[Helper]:[Sign3]]; 2;FALSE)&")"
A17: 14° | G17: Chiron | U17: words together | V17: C15&" "&E15&" "&F15&" "&H15&" "&I15&" "&K15&" "&L15&" "&O15&" "&Q15
A18: 15° | G18: BML
A19: 16° | G19: BML (o)
A20: 17° | G20: NN
A21: 18° | G21: SN
A22: 19°
A23: 20°
A24: 21°
A25: 22°
A26: 23°
A27: 24°
A28: 25°
A29: 26°
A30: 27°
A31: 28° | O31: Practice2
A32: 29°
O33: PLANET
O34: Stolpec1 | P34: Stolpec2
O35: 1 | P35: =Practice2!Z29 -> URANUS is Aries, with Libra spark in Aries decan, expressed through Sagittarius with Gemini base (through Aquarius)
O36: 2 | P36: =Practice2!Z30 -> URANUS is Aries, with Libra spark in Aries decan, expressed through Sagittarius with Gemini and 0 base (through Aquarius and )
O38: RULER
O39: Stolpec1 | P39: Stolpec2
O40: 1 | P40: =Practice2!$Z$25 -> JUPITER in Gemini, with Gemini spark in Gemini decan, expressed through Aquarius with Aries base (through Sagittarius)
O41: 2 | P41: =Practice2!Z26 -> JUPITER in Gemini, with Gemini spark in Gemini decan, expressed through Aquarius with Aries and 0 base (through Sagittarius and )
O43: Sentence | P43: Stolpec1
...

Sheet Spark_DataBase
B2: Degree | C2: Sign | D2: Helper | E2: Spark | F2: Decan | G2: Decan Planets
B3: 0° | C3: Aries | D3: =B3&"-"&C3 -> 0°-Aries | E3: Aries | F3: Aries | G3: MARS
B4: 0° | C4: Taurus | D4: =B4&"-"&C4 -> 0°-Taurus | E4: Libra | F4: Taurus | G4: VENUS (Taurus)
B5: 0° | C5: Gemini | D5: =B5&"-"&C5 -> 0°-Gemini | E5: Aries | F5: Gemini | G5: MERCURY (Gemini)
B6: 0° | C6: Cancer | D6: =B6&"-"&C6 -> 0°-Cancer | E6: Libra | F6: Cancer | G6: MOON
B7: 0° | C7: Leo | D7: =B7&"-"&C7 -> 0°-Leo | E7: Aries | F7: Leo | G7: SUN
B8: 0° | C8: Virgo | D8: =B8&"-"&C8 -> 0°-Virgo | E8: Libra | F8: Virgo | G8: MERCURY (Virgo)
B9: 0° | C9: Libra | D9: =B9&"-"&C9 -> 0°-Libra | E9: Aries | F9: Libra | G9: VENUS (Libra)
B10: 0° | C10: Scorpio | D10: =B10&"-"&C10 -> 0°-Scorpio | E10: Libra | F10: Scorpio | G10: PLUTO
B11: 0° | C11: Sagittarius | D11: =B11&"-"&C11 -> 0°-Sagittarius | E11: Aries | F11: Sagittarius | G11: JUPITER
B12: 0° | C12: Capricorn | D12: =B12&"-"&C12 -> 0°-Capricorn | E12: Libra | F12: Capricorn | G12: SATURN
B13: 0° | C13: Aquarius | D13: =B13&"-"&C13 -> 0°-Aquarius | E13: Aries | F13: Aquarius | G13: URANUS
B14: 0° | C14: Pisces | D14: =B14&"-"&C14 -> 0°-Pisces | E14: Libra | F14: Pisces | G14: NEPTUNE
... B362: 29° | C362: Pisces | D362: =B362&"-"&C362 -> 29°-Pisces | E362: Pisces | F362: Scorpio | G362: PLUTO

Sheet TruePlacement_DataBase1
E1: IS | G1: expressing through | H1: coming from
A3: Planet | B3: Sign | C3: Rising | D3: Helper | E3: IS house | F3: IS sign | G3: Sign2 | H3: BASE house | I3: BASE sign | J3: Sign3 | K3: Sign4 | L3: Sign5 | M3: Sign6
A4: MOON | B4: Aries | C4: Aries | D4: =A4&"-"&B4&"-"&C4 -> MOON-Aries-Aries | E4: 1st | F4: Aries | G4: Aries | H4: 4th | I4: Cancer | J4: Cancer
A5: MOON | B5: Aries | C5: Taurus | D5: =A5&"-"&B5&"-"&C5 -> MOON-Aries-Taurus | E5: 12th | F5: Pisces | G5: Aries | H5: 3rd | I5: Gemini | J5: Cancer
A6: MOON | B6: Aries | C6: Gemini | D6: =A6&"-"&B6&"-"&C6 -> MOON-Aries-Gemini | E6: 11th | F6: Aquarius | G6: Aries | H6: 2nd | I6: Taurus | J6: Cancer
A7: MOON | B7: Aries | C7: Cancer | D7: =A7&"-"&B7&"-"&C7 -> MOON-Aries-Cancer | E7: 10th | F7: Capricorn | G7: Aries | H7: 1st | I7: Aries | J7: Cancer
A8: MOON | B8: Aries | C8: Leo | D8: =A8&"-"&B8&"-"&C8 -> MOON-Aries-Leo | E8: 9th | F8: Sagittarius | G8: Aries | H8: 12th | I8: Pisces | J8: Cancer
A9: MOON | B9: Aries | C9: Virgo | D9: =A9&"-"&B9&"-"&C9 -> MOON-Aries-Virgo | E9: 8th | F9: Scorpio | G9: Aries | H9: 11th | I9: Aquarius | J9: Cancer
A10: MOON | B10: Aries | C10: Libra | D10: =A10&"-"&B10&"-"&C10 -> MOON-Aries-Libra | E10: 7th | F10: Libra | G10: Aries | H10: 10th | I10: Capricorn | J10: Cancer
A11: MOON | B11: Aries | C11: Scorpio | D11: =A11&"-"&B11&"-"&C11 -> MOON-Aries-Scorpio | E11: 6th | F11: Virgo | G11: Aries | H11: 9th | I11: Sagittarius | J11: Cancer
A12: MOON | B12: Aries | C12: Sagittarius | D12: =A12&"-"&B12&"-"&C12 -> MOON-Aries-Sagittarius | E12: 5th | F12: Leo | G12: Aries | H12: 8th | I12: Scorpio | J12: Cancer
A13: MOON | B13: Aries | C13: Capricorn | D13: =A13&"-"&B13&"-"&C13 -> MOON-Aries-Capricorn | E13: 4th | F13: Cancer | G13: Aries | H13: 7th | I13: Libra | J13: Cancer
A14: MOON | B14: Aries | C14: Aquarius | D14: =A14&"-"&B14&"-"&C14 -> MOON-Aries-Aquarius | E14: 3rd | F14: Gemini | G14: Aries | H14: 6th | I14: Virgo | J14: Cancer
A15: MOON | B15: Aries | C15: Pisces | D15: =A15&"-"&B15&"-"&C15 -> MOON-Aries-Pisces | E15: 2nd | F15: Taurus | G15: Aries | H15: 5th | I15: Leo | J15: Cancer
... A1155: NEPTUNE | B1155: Pisces | C1155: Pisces | D1155: =A1155&"-"&B1155&"-"&C1155 -> NEPTUNE-Pisces-Pisces | E1155: 1st | F1155: Aries | G1155: Pisces | H1155: 1st | I1155: Aries | J1155: Pisces
A1156: VENUS | B1156: Aries | C1156: Aries | D1156: =A1156&"-"&B1156&"-"&C1156 -> VENUS-Aries-Aries | E1156: 1st | F1156: Aries | G1156: Aries | H1156: 2nd | I1156: Taurus | J1156: Taurus | K1156: 7th | L1156: Libra | M1156: Libra
A1157: VENUS | B1157: Aries | C1157: Taurus | D1157: =A1157&"-"&B1157&"-"&C1157 -> VENUS-Aries-Taurus | E1157: 12th | F1157: Pisces | G1157: Aries | H1157: 1st | I1157: Aries | J1157: Taurus | K1157: 6th | L1157: Virgo | M1157: Libra
A1158: VENUS | B1158: Aries | C1158: Gemini | D1158: =A1158&"-"&B1158&"-"&C1158 -> VENUS-Aries-Gemini | E1158: 11th | F1158: Aquarius | G1158: Aries | H1158: 12th | I1158: Pisces | J1158: Taurus | K1158: 5th | L1158: Leo | M1158: Libra
A1159: VENUS | B1159: Aries | C1159: Cancer | D1159: =A1159&"-"&B1159&"-"&C1159 -> VENUS-Aries-Cancer | E1159: 10th | F1159: Capricorn | G1159: Aries | H1159: 11th | I1159: Aquarius | J1159: Taurus | K1159: 4th | L1159: Cancer | M1159: Libra
A1160: VENUS | B1160: Aries | C1160: Leo | D1160: =A1160&"-"&B1160&"-"&C1160 -> VENUS-Aries-Leo | E1160: 9th | F1160: Sagittarius | G1160: Aries | H1160: 10th | I1160: Capricorn | J1160: Taurus | K1160: 3rd | L1160: Gemini | M1160: Libra
A1161: VENUS | B1161: Aries | C1161: Virgo | D1161: =A1161&"-"&B1161&"-"&C1161 -> VENUS-Aries-Virgo | E1161: 8th | F1161: Scorpio | G1161: Aries | H1161: 9th | I1161: Sagittarius | J1161: Taurus | K1161: 2nd | L1161: Taurus | M1161: Libra
A1162: VENUS | B1162: Aries | C1162: Libra | D1162: =A1162&"-"&B1162&"-"&C1162 -> VENUS-Aries-Libra | E1162: 7th | F1162: Libra | G1162: Aries | H1162: 8th | I1162: Scorpio | J1162: Taurus | K1162: 1st | L1162: Aries | M1162: Libra
A1163: VENUS | B1163: Aries | C1163: Scorpio | D1163: =A1163&"-"&B1163&"-"&C1163 -> VENUS-Aries-Scorpio | E1163: 6th | F1163: Virgo | G1163: Aries | H1163: 7th | I1163: Libra | J1163: Taurus | K1163: 12th | L1163: Pisces | M1163: Libra
A1164: VENUS | B1164: Aries | C1164: Sagittarius | D1164: =A1164&"-"&B1164&"-"&C1164 -> VENUS-Aries-Sagittarius | E1164: 5th | F1164: Leo | G1164: Aries | H1164: 6th | I1164: Virgo | J1164: Taurus | K1164: 11th | L1164: Aquarius | M1164: Libra
A1165: VENUS | B1165: Aries | C1165: Capricorn | D1165: =A1165&"-"&B1165&"-"&C1165 -> VENUS-Aries-Capricorn | E1165: 4th | F1165: Cancer | G1165: Aries | H1165: 5th | I1165: Leo | J1165: Taurus | K1165: 10th | L1165: Capricorn | M1165: Libra
A1166: VENUS | B1166: Aries | C1166: Aquarius | D1166: =A1166&"-"&B1166&"-"&C1166 -> VENUS-Aries-Aquarius | E1166: 3rd | F1166: Gemini | G1166: Aries | H1166: 4th | I1166: Cancer | J1166: Taurus | K1166: 9th | L1166: Sagittarius | M1166: Libra
A1167: VENUS | B1167: Aries | C1167: Pisces | D1167: =A1167&"-"&B1167&"-"&C1167 -> VENUS-Aries-Pisces | E1167: 2nd | F1167: Taurus | G1167: Aries | H1167: 3rd | I1167: Gemini | J1167: Taurus | K1167: 8th | L1167: Scorpio | M1167: Libra
... A1443: MERCURY | B1443: Pisces | C1443: Pisces | D1443: =A1443&"-"&B1443&"-"&C1443 -> MERCURY-Pisces-Pisces | E1443: 1st | F1443: Aries | G1443: Pisces | H1443: 4th | I1443: Cancer | J1443: Gemini | K1443: 7th | L1443: Libra | M1443: Virgo

Sheet TruePlacement_DataBase2
E1: IS | G1: expressing through | H1: coming from | K1: 8 | L1: 9 | M1: 10
A3: Planet | B3: House | C3: Rising | D3: Helper | E3: IS house | F3: IS sign | G3: Sign | H3: BASE house | I3: BASE sign | J3: Sign2 | K3: BASE house3 | L3: BASE sign4 | M3: Sign5
A4: VENUS | B4: Aries | C4: Aries | D4: =A4&"-"&B4&"-"&C4 -> VENUS-Aries-Aries | E4: 1st | F4: Aries | G4: Aries | H4: 2nd | I4: Taurus | J4: Taurus | K4: 7th | L4: Libra | M4: Libra
A5: VENUS | B5: Aries | C5: Taurus | D5: =A5&"-"&B5&"-"&C5 -> VENUS-Aries-Taurus | E5: 12th | F5: Pisces | G5: Aries | H5: 1st | I5: Aries | J5: Taurus | K5: 6th | L5: Virgo | M5: Libra
A6: VENUS | B6: Aries | C6: Gemini | D6: =A6&"-"&B6&"-"&C6 -> VENUS-Aries-Gemini | E6: 11th | F6: Aquarius | G6: Aries | H6: 12th | I6: Pisces | J6: Taurus | K6: 5th | L6: Leo | M6: Libra
A7: VENUS | B7: Aries | C7: Cancer | D7: =A7&"-"&B7&"-"&C7 -> VENUS-Aries-Cancer | E7: 10th | F7: Capricorn | G7: Aries | H7: 11th | I7: Aquarius | J7: Taurus | K7: 4th | L7: Cancer | M7: Libra
A8: VENUS | B8: Aries | C8: Leo | D8: =A8&"-"&B8&"-"&C8 -> VENUS-Aries-Leo | E8: 9th | F8: Sagittarius | G8: Aries | H8: 10th | I8: Capricorn | J8: Taurus | K8: 3rd | L8: Gemini | M8: Libra
A9: VENUS | B9: Aries | C9: Virgo | D9: =A9&"-"&B9&"-"&C9 -> VENUS-Aries-Virgo | E9: 8th | F9: Scorpio | G9: Aries | H9: 9th | I9: Sagittarius | J9: Taurus | K9: 2nd | L9: Taurus | M9: Libra
A10: VENUS | B10: Aries | C10: Libra | D10: =A10&"-"&B10&"-"&C10 -> VENUS-Aries-Libra | E10: 7th | F10: Libra | G10: Aries | H10: 8th | I10: Scorpio | J10: Taurus | K10: 1st | L10: Aries | M10: Libra
A11: VENUS | B11: Aries | C11: Scorpio | D11: =A11&"-"&B11&"-"&C11 -> VENUS-Aries-Scorpio | E11: 6th | F11: Virgo | G11: Aries | H11: 7th | I11: Libra | J11: Taurus | K11: 12th | L11: Pisces | M11: Libra
A12: VENUS | B12: Aries | C12: Sagittarius | D12: =A12&"-"&B12&"-"&C12 -> VENUS-Aries-Sagittarius | E12: 5th | F12: Leo | G12: Aries | H12: 6th | I12: Virgo | J12: Taurus | K12: 11th | L12: Aquarius | M12: Libra
A13: VENUS | B13: Aries | C13: Capricorn | D13: =A13&"-"&B13&"-"&C13 -> VENUS-Aries-Capricorn | E13: 4th | F13: Cancer | G13: Aries | H13: 5th | I13: Leo | J13: Taurus | K13: 10th | L13: Capricorn | M13: Libra
A14: VENUS | B14: Aries | C14: Aquarius | D14: =A14&"-"&B14&"-"&C14 -> VENUS-Aries-Aquarius | E14: 3rd | F14: Gemini | G14: Aries | H14: 4th | I14: Cancer | J14: Taurus | K14: 9th | L14: Sagittarius | M14: Libra
A15: VENUS | B15: Aries | C15: Pisces | D15: =A15&"-"&B15&"-"&C15 -> VENUS-Aries-Pisces | E15: 2nd | F15: Taurus | G15: Aries | H15: 3rd | I15: Gemini | J15: Taurus | K15: 8th | L15: Scorpio | M15: Libra
... A291: MERCURY | B291: Pisces | C291: Pisces | D291: =A291&"-"&B291&"-"&C291 -> MERCURY-Pisces-Pisces | E291: 1st | F291: Aries | G291: Pisces | H291: 4th | I291: Cancer | J291: Gemini | K291: 7th | L291: Libra | M291: Virgo

Sheet TruePlacement_DataBase3
E1: IS | G1: expressing through | H1: coming from
